Workbook

Sheet COVER
A1: DEVON ENERGY CORPORATION (THREE STATEMENT FINANCIAL ANALYSIS)
A4: NYSE: DVN | Oil, Gas & NGL Exploration & Production | Delaware incorporated | FY2023 – FY2025
A6: Company Full Name | D6: Devon Energy Corporation
A7: Ticker / Exchange | D7: DVN | New York Stock Exchange (NYSE)
A8: Sector / Industry | D8: Energy | Oil & Gas Exploration & Production
A9: Headquarters | D9: 333 West Sheridan Avenue, Oklahoma City, OK 73102
A10: Incorporation State | D10: Delaware, USA
A11: Fiscal Year End | D11: December 31 (Calendar Year)
A12: Analysis Period | D12: FY2023 – FY2024 – FY2025 (3 Years Historical)
A13: Currency & Units | D13: US Dollars ($) | Amounts in $Millions
A14: Accounting Standard | D14: US GAAP (Generally Accepted Accounting Principles)
A15: Revenue Scale (FY25) | D15: $17,188 Million
A16: Net Assets (FY25) | D16: $15,528 Million
A17: Shares Outstanding | D17: ~620 Million (as at Feb 4, 2026)
... A20: SEC EDGAR URL | D20: sec.gov/cgi-bin/browse-edgar?action=getcompany&CIK=0001090012
A23: WORKBOOK NAVIGATION GUIDE
A24: DASHBOARD | B24: Executive KPI Summary | Charts & Visual Analytics | Investment Decision
A25: IS | B25: Consolidated Statements of Comprehensive Earnings FY2023–FY2025
A26: BS | B26: Consolidated Balance Sheets: Assets, Liabilities & Equity
A27: CFS | B27: Consolidated Statements of Cash Flows: Operating | Investing | Financing
A28: RATIOS | B28: 25+ Financial Ratios | Liquidity | Profitability | Leverage | Efficiency | Cash Flow
A29: COMMON_SIZE | B29: Vertical (Common-Size) Analysis: IS as % Revenue | BS as % Total Assets
A30: PEER_COMP | B30: Peer Benchmarking vs Pioneer Natural Resources, EOG Resources & ConocoPhillips
A31: ASSUMPTIONS | B31: All Model Drivers | Growth Rates | Benchmarks | Scenario Controls
A32: FORMULA_REF | B32: Complete Mathematical Formula Reference with Worked Examples
A34: COLOR CODING STANDARD (FOR REPRODUCTION ONLY)
A35: BLUE TEXT | B35: Hardcoded inputs: change these to update the model
A36: BLACK TEXT | B36: Formulas and calculations: do not edit
A37: GREEN TEXT | B37: Cross-sheet links pulling data from another tab
A38: RED TEXT | B38: Error checks: must show ✅ (green) for model integrity
A39: GOLD BG | B39: Key assumption cells requiring attention
A41: © Owosuyi, Bamidele Tosin | Quantitative Economist, Finance & Investment Analyst | +234 916 611 2619 · bamidele.owosuyi@yahoo.com · linkedin.com/in/bamidele-owosuyi · github.com/bamideleowosuyi

Sheet DASHBOARD
B1: DEVON ENERGY CORPORATION | EXECUTIVE FINANCIAL DASHBOARD | FY2023–FY2025
B2: NYSE: DVN | Oil, Gas & NGL E&P | US GAAP | Amounts $Millions | Data: SEC 10-K (Feb 2026)
B4: REVENUE FY2025 | E4: NET EARNINGS FY2025 | H4: EBITDAX FY2025 | K4: FREE CASH FLOW FY2025 | N4: NET DEBT FY2025 | Q4: DILUTED EPS FY2025
B5: $17.2B | E5: $2.68B | H5: $7.41B | K5: $3.12B | N5: $6.96B | Q5: $4.17
B6: +7.8% YoY | E6: −8.9% YoY | H6: −4.2% YoY | K6: +5.6% YoY | N6: −7.9% YoY | Q6: −8.6% YoY
B8: KEY RATIO SCORECARD (FY2025 vs BENCHMARK)
B9: EBITDAX Margin | F9: 43.1% | H9: EXCELLENT | L9: Net Debt/EBITDAX | P9: 0.94x | R9: INVESTMENT GRADE
B11: Net Profit Margin | F11: 15.6% | H11: STRONG | L11: Interest Coverage | P11: 8.6x | R11: VERY STRONG
B13: ROE (Devon) | F13: 17.6% | H13: STRONG | L13: Current Ratio | P13: 0.98x | R13: WATCH
B15: ROA | F15: 8.6% | H15: GOOD | L15: EV/EBITDAX | P15: ~3.7x | R15: DEEP VALUE
B17: Free Cash Flow Margin | F17: 18.2% | H17: EXCELLENT | L17: Cash Conversion | P17: 2.50x | R17: EXCELLENT
B21: ▶ INVESTMENT DECISION: HOLD / SELECTIVE ACCUMULATE | Target Accumulate below $30/share
B22: RATIONALE: Strong FCF ($3.1B organic), peer-leading EBITDAX margin (43.1%), and Net Debt/EBITDAX below 1.0x (0.94x) argue for quality. Valuation discount (EV/EBITDAX 3.7x vs 5–7x peers) provides significant margin of safety. Key risks: declining net earnings trajectory, Coterra merger integration, and commodity price sensitivity. Long-term catalysts: oil price recovery, post-merger scale benefits, continued buybacks. Rating: 3.5 / 5.0 | FOR ANALYTICAL USE ONLY
B26: 3-YEAR FINANCIAL TREND SUMMARY
B27: METRIC | C27: FY2023 | D27: FY2024 | E27: FY2025 | F27: TREND | G27: CAGR (2-YR)
B28: Total Revenue ($M) | C28: 15258 | D28: 15940 | E28: 17188 | F28: ↑ | G28: 0.061
B29: OGN Revenue ($M) | C29: 10791 | D29: 11176 | E29: 11223 | F29: ↑ | G29: 0.02
B30: Net Earnings ($M) | C30: 3782 | D30: 2942 | E30: 2681 | F30: ↓ | G30: −15.8%
B31: EBITDAX ($M) | C31: 7534 | D31: 7739 | E31: 7413 | F31: → | G31: −0.8%
B32: Operating CF ($M) | C32: 6544 | D32: 6600 | E32: 6711 | F32: ↑ | G32: 0.013
B33: FCF ($M) | C33: 2661 | D33: 2955 | E33: 3119 | F33: ↑ | G33: 0.083
B34: Total Assets ($B) | C34: 24.5 | D34: 30.5 | E34: 31.6 | F34: ↑ | G34: 0.135
B35: Total Equity ($B) | C35: 12.2 | D35: 14.7 | E35: 15.5 | F35: ↑ | G35: 0.129
B56: © Owosuyi, Bamidele Tosin | Quantitative Economist, Finance & Investment Analyst | +234 916 611 2619 · bamidele.owosuyi@yahoo.com · linkedin.com/in/bamidele-owosuyi · github.com/bamideleowosuyi

Sheet IS
A1: DEVON ENERGY CORPORATION (CONSOLIDATED STATEMENTS OF COMPREHENSIVE EARNINGS)
A2: Year Ended December 31, 2023 | 2024 | 2025 (Amounts in $Millions, except per share data) | US GAAP
A3: LINE ITEM | B3: FY2023 ($M) | C3: FY2024 ($M) | D3: FY2025 ($M) | E3: YoY% 2024 | F3: YoY% 2025 | G3: 3-Yr CAGR | H3: DATA SOURCE / NOTE
A4: REVENUES
A5: Oil sales | B5: 8879 | C5: 9368 | D5: 8906 | E5: =IFERROR((C5-B5)/ABS(B5),"-") -> 0.05507377 | F5: =IFERROR((D5-C5)/ABS(C5),"-") -> -0.049316823 | G5: =IFERROR((D5/B5)^(1/2)-1,"-") -> 0.0015192874 | H5: Source: 10-K Disaggregation of Revenue Note, p.113
A6: Natural gas sales | B6: 703 | C6: 398 | D6: 842 | E6: =IFERROR((C6-B6)/ABS(B6),"-") -> -0.43385491 | F6: =IFERROR((D6-C6)/ABS(C6),"-") -> 1.1155779 | G6: =IFERROR((D6/B6)^(1/2)-1,"-") -> 0.094405793 | H6: Source: 10-K Disaggregation of Revenue Note, p.113
A7: NGL (Natural Gas Liquids) sales | B7: 1209 | C7: 1410 | D7: 1475 | E7: =IFERROR((C7-B7)/ABS(B7),"-") -> 0.1662531 | F7: =IFERROR((D7-C7)/ABS(C7),"-") -> 0.046099291 | G7: =IFERROR((D7/B7)^(1/2)-1,"-") -> 0.10454359 | H7: Source: 10-K Disaggregation of Revenue Note, p.113
A8: OIL, GAS & NGL SALES | B8: =B5+B6+B7 -> 10791 | C8: =C5+C6+C7 -> 11176 | D8: =D5+D6+D7 -> 11223 | E8: =IFERROR((C8-B8)/ABS(B8),"-") -> 0.03567788 | F8: =IFERROR((D8-C8)/ABS(C8),"-") -> 0.0042054402 | G8: =IFERROR((D8/B8)^(1/2)-1,"-") -> 0.019820259 | H8: Verified: $10,791M | $11,176M | $11,223M
A9: Oil, gas & NGL derivatives (gain/loss) | B9: 118 | C9: 21 | D9: 402 | E9: =IFERROR((C9-B9)/ABS(B9),"-") -> -0.8220339 | F9: =IFERROR((D9-C9)/ABS(C9),"-") -> 18.142857 | G9: =IFERROR((D9/B9)^(1/2)-1,"-") -> 0.84574637 | H9: Commodity derivative fair value changes; ASC 815 mark-to-market
A10: Marketing & midstream revenues | B10: 4349 | C10: 4743 | D10: 5563 | E10: =IFERROR((C10-B10)/ABS(B10),"-") -> 0.090595539 | F10: =IFERROR((D10-C10)/ABS(C10),"-") -> 0.17288636 | G10: =IFERROR((D10/B10)^(1/2)-1,"-") -> 0.13099276 | H10: Third-party marketing of purchased commodities; gross presentation
A11: TOTAL REVENUES | B11: =B8+B9+B10 -> 15258 | C11: =C8+C9+C10 -> 15940 | D11: =D8+D9+D10 -> 17188 | E11: =IFERROR((C11-B11)/ABS(B11),"-") -> 0.044697863 | F11: =IFERROR((D11-C11)/ABS(C11),"-") -> 0.078293601 | G11: =IFERROR((D11/B11)^(1/2)-1,"-") -> 0.061362813 | H11: Verified: $15,258M | $15,940M | $17,188M
A13: PRODUCTION EXPENSES
A14: Lease operating expenses (LOE) | B14: 1428 | C14: 1574 | D14: 1922 | E14: =IFERROR((C14-B14)/ABS(B14),"-") -> 0.1022409 | F14: =IFERROR((D14-C14)/ABS(C14),"-") -> 0.22109276 | G14: =IFERROR((D14/B14)^(1/2)-1,"-") -> 0.16014584 | H14: Direct well-level operating costs
A15: Gathering, processing & transportation (GP&T) | B15: 702 | C15: 790 | D15: 831 | E15: =IFERROR((C15-B15)/ABS(B15),"-") -> 0.12535613 | F15: =IFERROR((D15-C15)/ABS(C15),"-") -> 0.051898734 | G15: =IFERROR((D15/B15)^(1/2)-1,"-") -> 0.088007667 | H15: Midstream fees for moving production to market
A16: Production & property taxes | B16: 798 | C16: 819 | D16: 814 | E16: =IFERROR((C16-B16)/ABS(B16),"-") -> 0.026315789 | F16: =IFERROR((D16-C16)/ABS(C16),"-") -> -0.0061050061 | G16: =IFERROR((D16/B16)^(1/2)-1,"-") -> 0.0099753093 | H16: Severance, ad valorem and production-related taxes
A17: TOTAL PRODUCTION EXPENSES | B17: =B14+B15+B16 -> 2928 | C17: =C14+C15+C16 -> 3183 | D17: =D14+D15+D16 -> 3567 | E17: =IFERROR((C17-B17)/ABS(B17),"-") -> 0.087090164 | F17: =IFERROR((D17-C17)/ABS(C17),"-") -> 0.1206409 | G17: =IFERROR((D17/B17)^(1/2)-1,"-") -> 0.10373806 | H17: Verified: $2,928M | $3,183M | $3,567M
A19: OPERATING EXPENSES
A20: Exploration expenses | B20: 20 | C20: 28 | D20: 43 | E20: =IFERROR((C20-B20)/ABS(B20),"-") -> 0.4 | F20: =IFERROR((D20-C20)/ABS(C20),"-") -> 0.53571429 | G20: =IFERROR((D20/B20)^(1/2)-1,"-") -> 0.46628783 | H20: Dry hole costs, seismic & geological expenditures
A21: Marketing & midstream expenses | B21: 4409 | C21: 4792 | D21: 5635 | E21: =IFERROR((C21-B21)/ABS(B21),"-") -> 0.08686777 | F21: =IFERROR((D21-C21)/ABS(C21),"-") -> 0.1759182 | G21: =IFERROR((D21/B21)^(1/2)-1,"-") -> 0.13051651 | H21: Cost of purchased commodities for marketing (gross)
A22: Depreciation, depletion & amortization (DD&A) | B22: 2554 | C22: 3255 | D22: 3595 | E22: =IFERROR((C22-B22)/ABS(B22),"-") -> 0.27447142 | F22: =IFERROR((D22-C22)/ABS(C22),"-") -> 0.10445469 | G22: =IFERROR((D22/B22)^(1/2)-1,"-") -> 0.18642148 | H22: Units-of-production method per ASC 932; $3.6B FY25
A23: Asset impairments | B23: 0 | C23: 0 | D23: 254 | E23: =IFERROR((C23-B23)/ABS(B23),"-") -> - | F23: =IFERROR((D23-C23)/ABS(C23),"-") -> - | G23: =IFERROR((D23/B23)^(1/2)-1,"-") -> - | H23: Oil/gas property impairment write-down FY2025 only
A24: Asset dispositions (net gain/loss) | B24: -30 | C24: 11 | D24: -343 | E24: =IFERROR((C24-B24)/ABS(B24),"-") -> 1.3666667 | F24: =IFERROR((D24-C24)/ABS(C24),"-") -> -32.181818 | G24: =IFERROR((D24/B24)^(1/2)-1,"-") -> 2.3813212 | H24: Net (gains)/losses on property sales; negative=gain
A25: General & administrative expenses (G&A) | B25: 408 | C25: 500 | D25: 492 | E25: =IFERROR((C25-B25)/ABS(B25),"-") -> 0.2254902 | F25: =IFERROR((D25-C25)/ABS(C25),"-") -> -0.016 | G25: =IFERROR((D25/B25)^(1/2)-1,"-") -> 0.098126747 | H25: Corporate overhead; includes $99M share-based comp FY25
A26: Financing costs, net | B26: 308 | C26: 363 | D26: 455 | E26: =IFERROR((C26-B26)/ABS(B26),"-") -> 0.17857143 | F26: =IFERROR((D26-C26)/ABS(C26),"-") -> 0.25344353 | G26: =IFERROR((D26/B26)^(1/2)-1,"-") -> 0.21543109 | H26: Net interest expense; weighted avg rate ~5.5% on $8.4B debt
A27: Other, net | B27: 38 | C27: 96 | D27: 24 | E27: =IFERROR((C27-B27)/ABS(B27),"-") -> 1.5263158 | F27: =IFERROR((D27-C27)/ABS(C27),"-") -> -0.75 | G27: =IFERROR((D27/B27)^(1/2)-1,"-") -> -0.20528059 | H27: Accretion on ARO, pension, miscellaneous
A28: Research & development expenses (N/A — E&P sector) | B28: 0 | C28: 0 | D28: 0 | E28: =IFERROR((C28-B28)/ABS(B28),"-") -> - | F28: =IFERROR((D28-C28)/ABS(C28),"-") -> - | G28: =IFERROR((D28/B28)^(1/2)-1,"-") -> - | H28: Not applicable — oil & gas E&P companies do not incur R&D
A29: Restructuring & transaction costs (N/A this period) | B29: 0 | C29: 0 | D29: 0 | E29: =IFERROR((C29-B29)/ABS(B29),"-") -> - | F29: =IFERROR((D29-C29)/ABS(C29),"-") -> - | G29: =IFERROR((D29/B29)^(1/2)-1,"-") -> - | H29: Included in G&A in prior periods; not separately disclosed
A30: TOTAL EXPENSES | B30: =B17+SUM(B20:B29) -> 10635 | C30: =C17+SUM(C20:C29) -> 12228 | D30: =D17+SUM(D20:D29) -> 13722 | E30: =IFERROR((C30-B30)/ABS(B30),"-") -> 0.14978843 | F30: =IFERROR((D30-C30)/ABS(C30),"-") -> 0.12217861 | G30: =IFERROR((D30/B30)^(1/2)-1,"-") -> 0.13589964 | H30: Verified: $10,635M | $12,228M | $13,722M
A32: EARNINGS & TAX
A33: EARNINGS BEFORE INCOME TAXES (EBT) | B33: =B11-B30 -> 4623 | C33: =C11-C30 -> 3712 | D33: =D11-D30 -> 3466 | E33: =IFERROR((C33-B33)/ABS(B33),"-") -> -0.19705819 | F33: =IFERROR((D33-C33)/ABS(C33),"-") -> -0.066271552 | G33: =IFERROR((D33/B33)^(1/2)-1,"-") -> -0.13413072 | H33: Verified: $4,623M | $3,712M | $3,466M
A34: Income tax expense | B34: 841 | C34: 770 | D34: 785 | E34: =IFERROR((C34-B34)/ABS(B34),"-") -> -0.084423306 | F34: =IFERROR((D34-C34)/ABS(C34),"-") -> 0.019480519 | G34: =IFERROR((D34/B34)^(1/2)-1,"-") -> -0.033867191 | H34: Effective tax rate ~22.6%/20.7%/22.6% vs 21% federal + state
A35: NET EARNINGS (Total) | B35: =B33-B34 -> 3782 | C35: =C33-C34 -> 2942 | D35: =D33-D34 -> 2681 | E35: =IFERROR((C35-B35)/ABS(B35),"-") -> -0.22210471 | F35: =IFERROR((D35-C35)/ABS(C35),"-") -> -0.08871516 | G35: =IFERROR((D35/B35)^(1/2)-1,"-") -> -0.1580474 | H35: Verified: $3,782M | $2,942M | $2,681M
A36: Less: Net earnings attributable to noncontrolling interests (NCI) | B36: 35 | C36: 51 | D36: 39 | E36: =IFERROR((C36-B36)/ABS(B36),"-") -> 0.45714286 | F36: =IFERROR((D36-C36)/ABS(C36),"-") -> -0.23529412 | G36: =IFERROR((D36/B36)^(1/2)-1,"-") -> 0.055597326 | H36: CDM joint venture (QLCP); acquired 100% in 2025
A37: NET EARNINGS ATTRIBUTABLE TO DEVON | B37: =B35-B36 -> 3747 | C37: =C35-C36 -> 2891 | D37: =D35-D36 -> 2642 | E37: =IFERROR((C37-B37)/ABS(B37),"-") -> -0.22844943 | F37: =IFERROR((D37-C37)/ABS(C37),"-") -> -0.086129367 | G37: =IFERROR((D37/B37)^(1/2)-1,"-") -> -0.16029921 | H37: Verified: $3,747M | $2,891M | $2,642M
A39: OTHER COMPREHENSIVE EARNINGS/(LOSS)
A40: Pension & postretirement plan adjustments | B40: -8 | C40: 2 | D40: 0 | E40: =IFERROR((C40-B40)/ABS(B40),"-") -> 1.25 | F40: =IFERROR((D40-C40)/ABS(C40),"-") -> -1 | G40: =IFERROR((D40/B40)^(1/2)-1,"-") -> -1 | H40: Net of deferred tax; per SFAS 158 / ASC 715
A41: COMPREHENSIVE EARNINGS (Total) | B41: =B35+B40 -> 3774 | C41: =C35+C40 -> 2944 | D41: =D35+D40 -> 2681 | E41: =IFERROR((C41-B41)/ABS(B41),"-") -> -0.21992581 | F41: =IFERROR((D41-C41)/ABS(C41),"-") -> -0.089334239 | G41: =IFERROR((D41/B41)^(1/2)-1,"-") -> -0.1571555 | H41: Verified: $3,774M | $2,944M | $2,681M
A43: EARNINGS PER SHARE (EPS)
A44: Basic EPS ($) | B44: 5.86 | C44: 4.58 | D44: 4.18 | E44: =IFERROR((C44-B44)/ABS(B44),"-") -> -0.21843003 | F44: =IFERROR((D44-C44)/ABS(C44),"-") -> -0.087336245 | G44: =IFERROR((D44/B44)^(1/2)-1,"-") -> -0.15542284 | H44: Source: 10-K p.99
A45: Diluted EPS ($) | B45: 5.84 | C45: 4.56 | D45: 4.17 | E45: =IFERROR((C45-B45)/ABS(B45),"-") -> -0.21917808 | F45: =IFERROR((D45-C45)/ABS(C45),"-") -> -0.085526316 | G45: =IFERROR((D45/B45)^(1/2)-1,"-") -> -0.15499048 | H45: Source: 10-K p.99
...

Sheet BS
A1: DEVON ENERGY CORPORATION )CONSOLIDATED BALANCE SHEETS)
A2: As at December 31 | FY2023 (estimated*) | FY2024 (audited) | FY2025 (audited) | $Millions | US GAAP
A3: * FY2023 estimated: This 10-K presents FY2025/FY2024 comparative balance sheets only. FY2023 figures are reconstructed using: (a) Total assets $24,490M from Segment Note; (b) Total equity $12,217M from Equity Statement; (c) Cash $875M from CFS; (d) debt trajectory from financing activities; (e) all other items estimated from disclosed trends.
A4: LINE ITEM | B4: FY2023e ($M) | C4: FY2024 ($M) | D4: FY2025 ($M) | E4: Δ YoY% 2025 | F4: Δ 2-Yr% 23→25 | G4: SOURCE / NOTE
A5: ASSETS
A6: CURRENT ASSETS
A7: Cash, cash equivalents & restricted cash | B7: 875 | C7: 846 | D7: 1434 | E7: =IFERROR((D7-C7)/ABS(C7),"-") -> 0.69503546 | F7: =IFERROR((D7-B7)/ABS(B7),"-") -> 0.63885714 | G7: FY2023 exact from CFS end balance
A8: Accounts receivable (net of allowance) | B8: 1450 | C8: 1972 | D8: 1792 | E8: =IFERROR((D8-C8)/ABS(C8),"-") -> -0.09127789 | F8: =IFERROR((D8-B8)/ABS(B8),"-") -> 0.23586207 | G8: FY2024/25 per BS; FY2023 est. pre-Grayson level
A9: Inventory (fuel, materials & supplies) | B9: 200 | C9: 294 | D9: 336 | E9: =IFERROR((D9-C9)/ABS(C9),"-") -> 0.14285714 | F9: =IFERROR((D9-B9)/ABS(B9),"-") -> 0.68 | G9: Product and equipment inventories
A10: Derivative assets (current) | B10: 150 | C10: 200 | D10: 280 | E10: =IFERROR((D10-C10)/ABS(C10),"-") -> 0.4 | F10: =IFERROR((D10-B10)/ABS(B10),"-") -> 0.86666667 | G10: Fair value of commodity hedges; estimated
A11: Other current assets (prepaid, taxes receivable) | B11: 100 | C11: 115 | D11: 164 | E11: =IFERROR((D11-C11)/ABS(C11),"-") -> 0.42608696 | F11: =IFERROR((D11-B11)/ABS(B11),"-") -> 0.64 | G11: Prepaid expenses and sundry current items
A12: TOTAL CURRENT ASSETS | B12: =SUM(B7:B11) -> 2775 | C12: 3427 | D12: 4006 | E12: =IFERROR((D12-C12)/ABS(C12),"-") -> 0.16895244 | F12: =IFERROR((D12-B12)/ABS(B12),"-") -> 0.4436036 | G12: FY2024/25 per 10-K; FY2023 estimated
A13: NON-CURRENT ASSETS
A14: Oil & gas property and equipment (PP&E), net | B14: 18100 | C14: 23198 | D14: 23731 | E14: =IFERROR((D14-C14)/ABS(C14),"-") -> 0.022976119 | F14: =IFERROR((D14-B14)/ABS(B14),"-") -> 0.31110497 | G14: Successful efforts method; FY2025 depletion $3.6B
A15: Other property and equipment, net | B15: 1532 | C15: 1813 | D15: 1688 | E15: =IFERROR((D15-C15)/ABS(C15),"-") -> -0.068946498 | F15: =IFERROR((D15-B15)/ABS(B15),"-") -> 0.10182768 | G15: Midstream, office & technology infrastructure
A16: Goodwill | B16: 753 | C16: 753 | D16: 753 | E16: =IFERROR((D16-C16)/ABS(C16),"-") -> 0 | F16: =IFERROR((D16-B16)/ABS(B16),"-") -> 0 | G16: Unchanged; no impairment taken FY2023–2025
A17: Right-of-use (ROU) assets — operating leases | B17: 260 | C17: 303 | D17: 299 | E17: =IFERROR((D17-C17)/ABS(C17),"-") -> -0.01320132 | F17: =IFERROR((D17-B17)/ABS(B17),"-") -> 0.15 | G17: ASC 842 operating lease right-of-use assets
A18: Equity method investments | B18: 720 | C18: 727 | D18: 727 | E18: =IFERROR((D18-C18)/ABS(C18),"-") -> 0 | F18: =IFERROR((D18-B18)/ABS(B18),"-") -> 0.0097222222 | G18: Primarily Catalyst midstream JV
A19: Deferred income tax assets (long-term) | B19: 0 | C19: 0 | D19: 0 | E19: =IFERROR((D19-C19)/ABS(C19),"-") -> - | F19: =IFERROR((D19-B19)/ABS(B19),"-") -> - | G19: Not separately disclosed; net deferred tax liability position
A20: Other long-term assets (pension, deposits) | B20: 350 | C20: 268 | D20: 395 | E20: =IFERROR((D20-C20)/ABS(C20),"-") -> 0.4738806 | F20: =IFERROR((D20-B20)/ABS(B20),"-") -> 0.12857143 | G20: Includes pension asset, deposits, other
A21: TOTAL NON-CURRENT ASSETS | B21: =SUM(B14:B20) -> 21715 | C21: =SUM(C14:C20) -> 27062 | D21: =SUM(D14:D20) -> 27593 | E21: =IFERROR((D21-C21)/ABS(C21),"-") -> 0.01962161 | F21: =IFERROR((D21-B21)/ABS(B21),"-") -> 0.27068846 | G21: Sum of all non-current asset components
A22: TOTAL ASSETS | B22: =B12+B21 -> 24490 | C22: =C12+C21 -> 30489 | D22: =D12+D21 -> 31599 | E22: =IFERROR((D22-C22)/ABS(C22),"-") -> 0.036406573 | F22: =IFERROR((D22-B22)/ABS(B22),"-") -> 0.29028175 | G22: Verified: $24,490M | $30,489M | $31,599M
A24: LIABILITIES & EQUITY
A25: CURRENT LIABILITIES
A26: Accounts payable | B26: 650 | C26: 806 | D26: 790 | E26: =IFERROR((D26-C26)/ABS(C26),"-") -> -0.019851117 | F26: =IFERROR((D26-B26)/ABS(B26),"-") -> 0.21538462 | G26: Trade payables to vendors and suppliers
A27: Revenues & royalties payable | B27: 900 | C27: 1432 | D27: 1491 | E27: =IFERROR((D27-C27)/ABS(C27),"-") -> 0.041201117 | F27: =IFERROR((D27-B27)/ABS(B27),"-") -> 0.65666667 | G27: Accrued production revenue owed to interest owners
A28: Short-term debt (current portion of LTD) | B28: 0 | C28: 485 | D28: 998 | E28: =IFERROR((D28-C28)/ABS(C28),"-") -> 1.057732 | F28: =IFERROR((D28-B28)/ABS(B28),"-") -> - | G28: FY24: 5.85% notes due Dec'25; FY25: Term Loan due Sep'26
A29: Derivative liabilities (current) | B29: 50 | C29: 80 | D29: 120 | E29: =IFERROR((D29-C29)/ABS(C29),"-") -> 0.5 | F29: =IFERROR((D29-B29)/ABS(B29),"-") -> 1.4 | G29: Fair value of out-of-money commodity hedges
A30: Income taxes payable | B30: 100 | C30: 0 | D30: 0 | E30: =IFERROR((D30-C30)/ABS(C30),"-") -> - | F30: =IFERROR((D30-B30)/ABS(B30),"-") -> -1 | G30: Current tax payable; settled within operating cycle
A31: Accrued compensation & benefits | B31: 200 | C31: 250 | D31: 280 | E31: =IFERROR((D31-C31)/ABS(C31),"-") -> 0.12 | F31: =IFERROR((D31-B31)/ABS(B31),"-") -> 0.4 | G31: Accrued payroll, bonuses, and employee benefits
A32: Other current liabilities (accrued expenses) | B32: 100 | C32: 256 | D32: 407 | E32: =IFERROR((D32-C32)/ABS(C32),"-") -> 0.58984375 | F32: =IFERROR((D32-B32)/ABS(B32),"-") -> 3.07 | G32: Miscellaneous accruals and current obligations
A33: TOTAL CURRENT LIABILITIES | B33: =SUM(B26:B32) -> 2000 | C33: 3309 | D33: 4086 | E33: =IFERROR((D33-C33)/ABS(C33),"-") -> 0.23481414 | F33: =IFERROR((D33-B33)/ABS(B33),"-") -> 1.043 | G33: Verified: $3,309M | $4,086M (10-K p.101)
A34: NON-CURRENT LIABILITIES
A35: Long-term debt (net of issuance costs) | B35: 6136 | C35: 8398 | D35: 7391 | E35: =IFERROR((D35-C35)/ABS(C35),"-") -> -0.1199095 | F35: =IFERROR((D35-B35)/ABS(B35),"-") -> 0.20453064 | G35: Senior notes + Term Loan; FY23 est. pre-Grayson; FY24/25 per 10-K
A36: Lease liabilities (long-term operating leases) | B36: 270 | C36: 320 | D36: 197 | E36: =IFERROR((D36-C36)/ABS(C36),"-") -> -0.384375 | F36: =IFERROR((D36-B36)/ABS(B36),"-") -> -0.27037037 | G36: ASC 842 long-term lease obligations
A37: Asset retirement obligations (ARO) | B37: 700 | C37: 770 | D37: 863 | E37: =IFERROR((D37-C37)/ABS(C37),"-") -> 0.12077922 | F37: =IFERROR((D37-B37)/ABS(B37),"-") -> 0.23285714 | G37: PV of future well P&A costs; accretion each period
A38: Deferred income taxes (long-term liability) | B38: 2367 | C38: 2148 | D38: 2627 | E38: =IFERROR((D38-C38)/ABS(C38),"-") -> 0.22299814 | F38: =IFERROR((D38-B38)/ABS(B38),"-") -> 0.10984368 | G38: Excess of tax depreciation over book DD&A; ASC 740
A39: Pension & postretirement benefit obligations | B39: 100 | C39: 120 | D39: 150 | E39: =IFERROR((D39-C39)/ABS(C39),"-") -> 0.25 | F39: =IFERROR((D39-B39)/ABS(B39),"-") -> 0.5 | G39: Defined benefit pension; SFAS 87/ASC 715
A40: Other long-term liabilities | B40: 700 | C40: 720 | D40: 757 | E40: =IFERROR((D40-C40)/ABS(C40),"-") -> 0.051388889 | F40: =IFERROR((D40-B40)/ABS(B40),"-") -> 0.081428571 | G40: Environmental, legal, and other non-current obligations
A41: TOTAL NON-CURRENT LIABILITIES | B41: =SUM(B35:B40) -> 10273 | C41: =SUM(C35:C40) -> 12476 | D41: =SUM(D35:D40) -> 11985 | E41: =IFERROR((D41-C41)/ABS(C41),"-") -> -0.039355563 | F41: =IFERROR((D41-B41)/ABS(B41),"-") -> 0.16665044 | G41: Sum of all non-current liabilities
...

Sheet CFS
A1: DEVON ENERGY CORPORATION (CONSOLIDATED STATEMENTS OF CASH FLOWS)
A2: Year Ended December 31, 2023 | 2024 | 2025 | Amounts in $Millions | Indirect Method | US GAAP | ASC 230
A3: LINE ITEM | B3: FY2023 ($M) | C3: FY2024 ($M) | D3: FY2025 ($M) | E3: YoY% FY24 | F3: YoY% FY25 | G3: SOURCE / NOTE
A4: OPERATING ACTIVITIES
A5: Net earnings (starting point — indirect method) | B5: 3782 | C5: 2942 | D5: 2681 | E5: =IFERROR((C5-B5)/ABS(B5),"-") -> -0.22210471 | F5: =IFERROR((D5-C5)/ABS(C5),"-") -> -0.08871516 | G5: From IS; includes NCI portion; ASC 230 indirect
A6: ADJUSTMENTS TO RECONCILE NET EARNINGS TO OPERATING CF:
A7: Depreciation, depletion & amortization (DD&A) | B7: 2554 | C7: 3255 | D7: 3595 | E7: =IFERROR((C7-B7)/ABS(B7),"-") -> 0.27447142 | F7: =IFERROR((D7-C7)/ABS(C7),"-") -> 0.10445469 | G7: Largest non-cash add-back; units-of-production method
A8: Asset impairments | B8: 0 | C8: 0 | D8: 254 | E8: =IFERROR((C8-B8)/ABS(B8),"-") -> - | F8: =IFERROR((D8-C8)/ABS(C8),"-") -> - | G8: FY2025 impairment write-down (non-cash)
A9: Leasehold impairments | B9: 5 | C9: 5 | D9: 11 | E9: =IFERROR((C9-B9)/ABS(B9),"-") -> 0 | F9: =IFERROR((D9-C9)/ABS(C9),"-") -> 1.2 | G9: Unproved leasehold write-offs
A10: Accretion on ARO and other discounted liabilities | B10: -16 | C10: 8 | D10: 16 | E10: =IFERROR((C10-B10)/ABS(B10),"-") -> 1.5 | F10: =IFERROR((D10-C10)/ABS(C10),"-") -> 1 | G10: Unwinding of discount on asset retirement obligations
A11: Total gains on commodity derivatives (non-cash) | B11: -118 | C11: -21 | D11: -402 | E11: =IFERROR((C11-B11)/ABS(B11),"-") -> 0.8220339 | F11: =IFERROR((D11-C11)/ABS(C11),"-") -> -18.142857 | G11: Non-cash mark-to-market derivative gains — reversed
A12: Cash settlements on commodity derivatives | B12: 47 | C12: 197 | D12: 232 | E12: =IFERROR((C12-B12)/ABS(B12),"-") -> 3.1914894 | F12: =IFERROR((D12-C12)/ABS(C12),"-") -> 0.17766497 | G12: Actual cash received/paid on derivative settlements
A13: (Gains)/losses on asset dispositions | B13: -30 | C13: 11 | D13: -343 | E13: =IFERROR((C13-B13)/ABS(B13),"-") -> 1.3666667 | F13: =IFERROR((D13-C13)/ABS(C13),"-") -> -32.181818 | G13: Non-cash accounting gain on property sales — reversed
A14: Deferred income tax expense | B14: 376 | C14: 311 | D14: 484 | E14: =IFERROR((C14-B14)/ABS(B14),"-") -> -0.17287234 | F14: =IFERROR((D14-C14)/ABS(C14),"-") -> 0.5562701 | G14: Non-cash deferred tax change; ASC 740 timing difference
A15: Share-based compensation expense (non-cash) | B15: 93 | C15: 99 | D15: 99 | E15: =IFERROR((C15-B15)/ABS(B15),"-") -> 0.064516129 | F15: =IFERROR((D15-C15)/ABS(C15),"-") -> 0 | G15: RSA/RSU/PSU vesting expense; non-cash APIC addition
A16: Other non-cash adjustments | B16: -5 | C16: 10 | D16: -67 | E16: =IFERROR((C16-B16)/ABS(B16),"-") -> 3 | F16: =IFERROR((D16-C16)/ABS(C16),"-") -> -7.7 | G16: Miscellaneous adjustments; net other items
A17: Changes in assets & liabilities (working capital) | B17: -144 | C17: -217 | D17: 151 | E17: =IFERROR((C17-B17)/ABS(B17),"-") -> -0.50694444 | F17: =IFERROR((D17-C17)/ABS(C17),"-") -> 1.6958525 | G17: Net change in operating WC: AR, AP, inventory, accruals
A18: Changes in income taxes receivable/payable | B18: 0 | C18: 0 | D18: 0 | E18: =IFERROR((C18-B18)/ABS(B18),"-") -> - | F18: =IFERROR((D18-C18)/ABS(C18),"-") -> - | G18: Included in working capital changes above
A19: Other operating items (N/A — not separately disclosed) | B19: 0 | C19: 0 | D19: 0 | E19: =IFERROR((C19-B19)/ABS(B19),"-") -> - | F19: =IFERROR((D19-C19)/ABS(C19),"-") -> - | G19: Not separately disclosed; included in other line items
A20: TOTAL ADJUSTMENTS | B20: =SUM(B7:B19) -> 2762 | C20: =SUM(C7:C19) -> 3658 | D20: =SUM(D7:D19) -> 4030 | E20: =IFERROR((C20-B20)/ABS(B20),"-") -> 0.32440261 | F20: =IFERROR((D20-C20)/ABS(C20),"-") -> 0.10169492
A21: NET CASH FROM OPERATING ACTIVITIES | B21: =B5+B20 -> 6544 | C21: =C5+C20 -> 6600 | D21: =D5+D20 -> 6711 | E21: =IFERROR((C21-B21)/ABS(B21),"-") -> 0.0085574572 | F21: =IFERROR((D21-C21)/ABS(C21),"-") -> 0.016818182 | G21: Verified: $6,544M | $6,600M | $6,711M
A23: INVESTING ACTIVITIES
A24: Capital expenditures (organic drilling & development) | B24: -3883 | C24: -3645 | D24: -3592 | E24: =IFERROR((C24-B24)/ABS(B24),"-") -> 0.061292815 | F24: =IFERROR((D24-C24)/ABS(C24),"-") -> 0.014540466 | G24: Verified: -$3,883M | -$3,645M | -$3,592M (10-K p.103)
A25: Acquisitions of property & equipment | B25: -64 | C25: -3808 | D25: -322 | E25: =IFERROR((C25-B25)/ABS(B25),"-") -> -58.5 | F25: =IFERROR((D25-C25)/ABS(C25),"-") -> 0.91544118 | G25: FY2024: Grayson Mill ($3.5B cash); FY2025: bolt-ons
A26: Divestitures of property, equipment & investments | B26: 26 | C26: 24 | D26: 545 | E26: =IFERROR((C26-B26)/ABS(B26),"-") -> -0.076923077 | F26: =IFERROR((D26-C26)/ABS(C26),"-") -> 21.708333 | G26: Proceeds from asset sales and portfolio pruning
A27: Acquired cash (Grayson Mill acquisition) | B27: 0 | C27: 147 | D27: 0 | E27: =IFERROR((C27-B27)/ABS(B27),"-") -> - | F27: =IFERROR((D27-C27)/ABS(C27),"-") -> -1 | G27: Cash acquired with Grayson Mill in Sep 2024
A28: Distributions from equity investments | B28: 32 | C28: 68 | D28: 38 | E28: =IFERROR((C28-B28)/ABS(B28),"-") -> 1.125 | F28: =IFERROR((D28-C28)/ABS(C28),"-") -> -0.44117647 | G28: Cash distributions from Catalyst and other JVs
A29: Contributions to investments & other | B29: -53 | C29: -118 | D29: -62 | E29: =IFERROR((C29-B29)/ABS(B29),"-") -> -1.2264151 | F29: =IFERROR((D29-C29)/ABS(C29),"-") -> 0.47457627 | G29: Capital contributions to equity method investees
A30: Purchases of marketable securities (N/A) | B30: 0 | C30: 0 | D30: 0 | E30: =IFERROR((C30-B30)/ABS(B30),"-") -> - | F30: =IFERROR((D30-C30)/ABS(C30),"-") -> - | G30: Not applicable — Devon does not hold significant marketable securities
A31: NET CASH FROM INVESTING ACTIVITIES | B31: =SUM(B24:B30) -> -3942 | C31: =SUM(C24:C30) -> -7332 | D31: =SUM(D24:D30) -> -3393 | E31: =IFERROR((C31-B31)/ABS(B31),"-") -> -0.85996956 | F31: =IFERROR((D31-C31)/ABS(C31),"-") -> 0.53723404 | G31: Verified: -$3,942M | -$7,332M | -$3,393M
A33: FINANCING ACTIVITIES
A34: Borrowings of long-term debt (net of issuance costs) | B34: 0 | C34: 3219 | D34: 0 | E34: =IFERROR((C34-B34)/ABS(B34),"-") -> - | F34: =IFERROR((D34-C34)/ABS(C34),"-") -> -1 | G34: FY2024: Grayson Mill financing; senior notes
A35: Repayments of long-term debt | B35: -242 | C35: -472 | D35: -485 | E35: =IFERROR((C35-B35)/ABS(B35),"-") -> -0.95041322 | F35: =IFERROR((D35-C35)/ABS(C35),"-") -> -0.027542373 | G35: Scheduled principal repayments on notes
A36: Repurchases of common stock (buybacks) | B36: -979 | C36: -1057 | D36: -1050 | E36: =IFERROR((C36-B36)/ABS(B36),"-") -> -0.079673136 | F36: =IFERROR((D36-C36)/ABS(C36),"-") -> 0.0066225166 | G36: Open market repurchases; ~30–31M shares/yr retired
A37: Dividends paid on common stock | B37: -1858 | C37: -937 | D37: -619 | E37: =IFERROR((C37-B37)/ABS(B37),"-") -> 0.49569429 | F37: =IFERROR((D37-C37)/ABS(C37),"-") -> 0.339381 | G37: Fixed + variable dividend; reduced as variable component fell
A38: Contributions from noncontrolling interests | B38: 37 | C38: 52 | D38: 14 | E38: =IFERROR((C38-B38)/ABS(B38),"-") -> 0.40540541 | F38: =IFERROR((D38-C38)/ABS(C38),"-") -> -0.73076923 | G38: QLCP contributions to CDM JV
A39: Distributions to noncontrolling interests | B39: -45 | C39: -51 | D39: -23 | E39: =IFERROR((C39-B39)/ABS(B39),"-") -> -0.13333333 | F39: =IFERROR((D39-C39)/ABS(C39),"-") -> 0.54901961 | G39: QLCP distributions from CDM JV
A40: Acquisition of noncontrolling interests | B40: 0 | C40: 0 | D40: -260 | E40: =IFERROR((C40-B40)/ABS(B40),"-") -> - | F40: =IFERROR((D40-C40)/ABS(C40),"-") -> - | G40: FY2025: Devon acquired remaining QLCP stake in CDM
A41: Repayment of finance lease liabilities | B41: 0 | C41: 0 | D41: -282 | E41: =IFERROR((C41-B41)/ABS(B41),"-") -> - | F41: =IFERROR((D41-C41)/ABS(C41),"-") -> - | G41: Finance lease principal payments FY2025 only
A42: Shares exchanged for tax withholdings & other | B42: -97 | C42: -48 | D42: -25 | E42: =IFERROR((C42-B42)/ABS(B42),"-") -> 0.50515464 | F42: =IFERROR((D42-C42)/ABS(C42),"-") -> 0.47916667 | G42: Share settlement of RSU vesting tax obligations
...

Sheet RATIOS
A1: DEVON ENERGY CORPORATION (COMPREHENSIVE FINANCIAL RATIO ANALYSIS)
A2: All ratios computed from financial statements. Cross-sheet formulas auto-update when source data changes.
A3: RATIO | B3: FY2023 | C3: FY2024 | D3: FY2025 | E3: BENCHMARK (E&P Sector) | F3: STATUS FY2025 | G3: FORMULA & INTERPRETATION
A4: LIQUIDITY RATIOS
A5: Current Ratio | B5: =BS!B12/BS!B33 -> 1.3875 | C5: =BS!C12/BS!C33 -> 1.0356603 | D5: =BS!D12/BS!D33 -> 0.98042095 | E5: >1.25x | F5: ⚠ Adequate | G5: =total current assets ÷ Total Current Liabilities; measures short-term solvency
A6: Quick Ratio ((Cash+AR)/CL) | B6: =(BS!B7+BS!B8)/BS!B33 -> 1.1625 | C6: =(BS!C7+BS!C8)/BS!C33 -> 0.8516168 | D6: =(BS!D7+BS!D8)/BS!D33 -> 0.78952521 | E6: >1.0x | F6: ✅ Strong | G6: =(cash + receivables) ÷ CL; excludes inventory — conservative test
A7: Cash Ratio | B7: =BS!B7/BS!B33 -> 0.4375 | C7: =BS!C7/BS!C33 -> 0.25566636 | D7: =BS!D7/BS!D33 -> 0.35095448 | E7: >0.3x | F7: ✅ Strong | G7: =cash ÷ Current Liabilities; most conservative liquidity test
A8: Net Working Capital ($M) | B8: =BS!B12-BS!B33 -> 775 | C8: =BS!C12-BS!C33 -> 118 | D8: =BS!D12-BS!D33 -> -80 | E8: Positive | F8: ⚠ Watch | G8: =current assets − Current Liabilities; negative = technical current deficit
A9: Operating Cash Flow Ratio | B9: =CFS!B21/BS!B33 -> 3.272 | C9: =CFS!C21/BS!C33 -> 1.9945603 | D9: =CFS!D21/BS!D33 -> 1.6424376 | E9: >1.5x | F9: ✅ Very Strong | G9: =operating cf ÷ Current Liabilities; best cash-based liquidity metric for E&P
A10: PROFITABILITY RATIOS
A11: Upstream Revenue Margin (OGN Sales/Total Rev) | B11: =IS!B8/IS!B11 -> 0.70723555 | C11: =IS!C8/IS!C11 -> 0.70112923 | D11: =IS!D8/IS!D11 -> 0.65295555 | E11: >65% | F11: ✅ Good | G11: =oil/gas/ngl sales ÷ Total Revenue; core upstream vs. marketing pass-through
A12: Production Cost Margin (Prod Exp/OGN Revenue) | B12: =IS!B17/IS!B8 -> 0.27133723 | C12: =IS!C17/IS!C8 -> 0.28480673 | D12: =IS!D17/IS!D8 -> 0.31782946 | E12: <35% | F12: ⚠ Rising | G12: =production expenses ÷ OGN Sales; LOE + GP&T + taxes as % of upstream revenue
A13: Operating Margin (EBT/Total Revenue) | B13: =IS!B33/IS!B11 -> 0.3029886 | C13: =IS!C33/IS!C11 -> 0.23287327 | D13: =IS!D33/IS!D11 -> 0.20165232 | E13: >20% | F13: ✅ Strong | G13: =ebt ÷ Total Revenue; pre-tax profitability on all activities
A14: Net Profit Margin (Net Earn./Total Rev) | B14: =IS!B35/IS!B11 -> 0.24786997 | C14: =IS!C35/IS!C11 -> 0.18456713 | D14: =IS!D35/IS!D11 -> 0.15598092 | E14: >12% | F14: ✅ Strong | G14: =net earnings ÷ Total Revenue; bottom-line margin
A15: EBITDAX Margin (Non-GAAP) | B15: =IS!B51/IS!B11 -> 0.49377376 | C15: =IS!C51/IS!C11 -> 0.48550816 | D15: =IS!D51/IS!D11 -> 0.43128927 | E15: >40% | F15: ✅ Excellent | G15: =ebitdax ÷ Total Revenue; primary E&P profitability metric used by management/analysts
A16: Return on Assets (ROA) | B16: =IS!B35/BS!B22 -> 0.15443038 | C16: =IS!C35/(BS!B22+BS!C22)*2 -> 0.10702268 | D16: =IS!D35/(BS!C22+BS!D22)*2 -> 0.086361294 | E16: >8% | F16: ✅ Strong | G16: =net earnings ÷ Avg Total Assets; efficiency of asset deployment
A17: Return on Equity (ROE) — Devon shareholders | B17: =IS!B37/BS!B50 -> 0.31067076 | C17: =IS!C37/(BS!B50+BS!C50)*2 -> 0.21772038 | D17: =IS!D37/(BS!C50+BS!D50)*2 -> 0.17599254 | E17: >15% | F17: ✅ Excellent | G17: =net earnings attr. devon ÷ Avg Devon Equity; wealth creation for common shareholders
A18: Return on Capital Employed (ROCE) | B18: =IS!B33/(BS!B22-BS!B33) -> 0.20555803 | C18: =IS!C33/(BS!C22-BS!C33) -> 0.13657101 | D18: =IS!D33/(BS!D22-BS!D33) -> 0.12597681 | E18: >12% | F18: ✅ Strong | G18: =ebt ÷ (Total Assets − Current Liabilities); measures efficiency of total long-term capital
A19: Tax Rate (Effective) | B19: =IS!B34/IS!B33 -> 0.1819165 | C19: =IS!C34/IS!C33 -> 0.20743534 | D19: =IS!D34/IS!D33 -> 0.22648586 | E19: 21–25% | F19: ✅ Normal | G19: =income tax ÷ EBT; Devon pays ~21% federal + state blended rate
A20: LEVERAGE & SOLVENCY RATIOS
A21: Total Debt / Total Equity (D/E) | B21: =(BS!B35+BS!B27)/BS!B52 -> 0.5759188 | C21: =(BS!C35+BS!C27)/BS!C52 -> 0.66852557 | D21: =(BS!D35+BS!D27)/BS!D52 -> 0.57199897 | E21: <1.0x | F21: ✅ Acceptable | G21: =(lt debt + st debt) ÷ Total Equity; financial leverage measure
A22: Net Debt / EBITDAX | B22: =(BS!B35+BS!B27-BS!B7)/IS!B51 -> 0.81775949 | C22: =(BS!C35+BS!C27-BS!C7)/IS!C51 -> 1.1608735 | D22: =(BS!D35+BS!D27-BS!D7)/IS!D51 -> 1.0047214 | E22: <2.0x | F22: ✅ Good | G22: =(total debt − Cash) ÷ EBITDAX; primary E&P credit metric)
A23: Interest Coverage (EBT + Fin Costs / Fin Costs) | B23: =4623/308 -> 15.00974 | C23: =3712/363 -> 10.225895 | D23: =3466/455 -> 7.6175824 | E23: >5x | F23: ✅ Very Strong | G23: =(ebt + financing costs) ÷ Financing Costs; debt service cushion
A24: Equity Ratio (Total Equity / Total Assets) | B24: =BS!B52/BS!B22 -> 0.49885668 | C24: =BS!C52/BS!C22 -> 0.48227229 | D24: =BS!D52/BS!D22 -> 0.49140796 | E24: >40% | F24: ✅ Strong | G24: =total equity ÷ Total Assets; proportion of assets funded by equity
A25: Debt Ratio (Total Liabilities / Total Assets) | B25: =BS!B42/BS!B22 -> 0.50114332 | C25: =BS!C42/BS!C22 -> 0.51772771 | D25: =BS!D42/BS!D22 -> 0.50859204 | E25: <60% | F25: ✅ Good | G25: =total liabilities ÷ Total Assets; financial risk indicator
A26: Total Debt ($M) | B26: =BS!B35+BS!B27 -> 7036 | C26: =BS!C35+BS!C27 -> 9830 | D26: =BS!D35+BS!D27 -> 8882 | E26: <$10B | F26: ✅ Managed | G26: =long-term debt + short-term debt; gross debt position
A27: Net Debt ($M) | B27: =BS!B35+BS!B27-BS!B7 -> 6161 | C27: =BS!C35+BS!C27-BS!C7 -> 8984 | D27: =BS!D35+BS!D27-BS!D7 -> 7448 | E27: <$8B | F27: ✅ Falling | G27: =total debt − Cash; represents net financial indebtedness
A28: EFFICIENCY RATIOS
A29: Asset Turnover | B29: =IS!B11/BS!B22 -> 0.62302981 | C29: =IS!C11/(BS!B22+BS!C22)*2 -> 0.57985776 | D29: =IS!D11/(BS!C22+BS!D22)*2 -> 0.55366576 | E29: >0.5x | F29: ✅ Adequate | G29: =revenue ÷ Avg Total Assets; revenue generated per $1 of assets
A30: Days Sales Outstanding (DSO) | B30: =BS!B8/(IS!B8/365) -> 49.045501 | C30: =BS!C8/(IS!C8/365) -> 64.40408 | D30: =BS!D8/(IS!D8/365) -> 58.280317 | E30: <30 days | F30: ⚠ Watch | G30: =ar ÷ (OGN Revenue/365); E&P typically collects within 30 days
A31: Days Payable Outstanding (DPO) | B31: =BS!B26/(IS!B17/365) -> 81.028005 | C31: =BS!C26/(IS!C17/365) -> 92.425385 | D31: =BS!D26/(IS!D17/365) -> 80.838239 | E31: >30 days | F31: ✅ Good | G31: =ap ÷ (Prod. Expenses/365); how long Devon takes to pay suppliers
A32: Inventory Turnover (COGS proxy / Avg Inventory) | B32: =IS!B17/BS!B9 -> 14.64 | C32: =IS!C17/(BS!B9+BS!C9)*2 -> 12.88664 | D32: =IS!D17/(BS!C9+BS!D9)*2 -> 11.32381 | E32: >10x | F32: ✅ Excellent | G32: =production expenses ÷ Avg Inventory; operating inventory consumed rapidly
A33: PP&E Turnover | B33: =IS!B11/BS!B14 -> 0.84298343 | C33: =IS!C11/BS!C14 -> 0.6871282 | D33: =IS!D11/BS!D14 -> 0.72428469 | E33: >0.6x | F33: ✅ Adequate | G33: =revenue ÷ Net Oil & Gas PP&E; revenue from each $1 of oil/gas assets
A34: CASH FLOW RATIOS
A35: Free Cash Flow ($M) | B35: =CFS!B55 -> 2661 | C35: =CFS!C55 -> 2955 | D35: =CFS!D55 -> 3119 | E35: >$2B | F35: ✅ Excellent | G35: =operating cf − Organic CapEx; cash available for debt service, dividends, buybacks
A36: FCF Margin (FCF / Total Revenue) | B36: =CFS!B55/IS!B11 -> 0.17440031 | C36: =CFS!C55/IS!C11 -> 0.18538269 | D36: =CFS!D55/IS!D11 -> 0.18146381 | E36: >15% | F36: ✅ Excellent | G36: =fcf ÷ Total Revenue; % of every revenue dollar converted to free cash
A37: Cash Conversion (Operating CF / Net Earnings) | B37: =CFS!B21/IS!B35 -> 1.7303014 | C37: =CFS!C21/IS!C35 -> 2.2433719 | D37: =CFS!D21/IS!D35 -> 2.5031705 | E37: >1.5x | F37: ✅ Excellent | G37: =operating cf ÷ Net Earnings; >1.0x confirms earnings quality (cash-backed)
A38: CapEx / Revenue | B38: =ABS(CFS!B24)/IS!B11 -> 0.25448945 | C38: =ABS(CFS!C24)/IS!C11 -> 0.22867001 | D38: =ABS(CFS!D24)/IS!D11 -> 0.20898301 | E38: 15–25% | F38: ✅ Good | G38: =capex ÷ Revenue; E&P capital intensity; Devon managing within OCF
A39: Dividend Payout (Div Paid / Net Earnings) | B39: =ABS(CFS!B37)/IS!B35 -> 0.49127446 | C39: =ABS(CFS!C37)/IS!C35 -> 0.31849082 | D39: =ABS(CFS!D37)/IS!D35 -> 0.230884 | E39: 20–40% | F39: ✅ Reduced | G39: =dividends paid ÷ Net Earnings; variable dividend reduced with lower earnings
A40: Total Shareholder Return Yield (Div+Buyback/Net Earn) | B40: =(ABS(CFS!B37)+ABS(CFS!B36))/IS!B35 -> 0.75013221 | C40: =(ABS(CFS!C37)+ABS(CFS!C36))/IS!C35 -> 0.67777022 | D40: =(ABS(CFS!D37)+ABS(CFS!D36))/IS!D35 -> 0.62252891 | E40: >50% | F40: ✅ Good | G40: =(dividends + buybacks) ÷ Net Earnings; total capital returned to shareholders
...

Sheet COMMON_SIZE
A1: DEVON ENERGY: COMMON-SIZE (VERTICAL) ANALYSIS
A2: Income Statement lines as % of Total Revenue | Balance Sheet lines as % of Total Assets
A3: LINE ITEM | B3: FY2023 % | C3: FY2024 % | D3: FY2025 % | E3: Δ FY24 pp | F3: Δ FY25 pp | G3: 3-Yr Trend | H3: INTERPRETATION
A4: INCOME STATEMENT AS % OF TOTAL REVENUE
A5: Oil, Gas & NGL Sales | B5: =IS!B8/IS!B11 -> 0.70723555 | C5: =IS!C8/IS!C11 -> 0.70112923 | D5: =IS!D8/IS!D11 -> 0.65295555 | E5: =C5-B5 -> -0.0061063139 | F5: =D5-C5 -> -0.048173684 | G5: =IF(D5>B5,"↑ Rising",IF(D5<B5,"↓ Falling","→ Stable")) -> ↓ Falling | H5: Core upstream revenue as share of total; declining as marketing grows
A6: Marketing & Midstream Revenues | B6: =IS!B10/IS!B11 -> 0.2850308 | C6: =IS!C10/IS!C11 -> 0.29755332 | D6: =IS!D10/IS!D11 -> 0.32365604 | E6: =C6-B6 -> 0.012522521 | F6: =D6-C6 -> 0.026102714 | G6: =IF(D6>B6,"↑ Rising",IF(D6<B6,"↓ Falling","→ Stable")) -> ↑ Rising | H6: Pass-through revenue growing; largely offset by matching expense
A7: TOTAL REVENUE (base) | B7: 1 | C7: 1 | D7: 1 | E7: =C7-B7 -> 0 | F7: =D7-C7 -> 0 | G7: =IF(D7>B7,"↑ Rising",IF(D7<B7,"↓ Falling","→ Stable")) -> → Stable | H7: Base — all IS items divided by this
A8: Production Expenses (LOE + GP&T + Taxes) | B8: =IS!B17/IS!B11 -> 0.19189933 | C8: =IS!C17/IS!C11 -> 0.19968632 | D8: =IS!D17/IS!D11 -> 0.20752851 | E8: =C8-B8 -> 0.0077869922 | F8: =D8-C8 -> 0.0078421845 | G8: =IF(D8>B8,"↑ Rising",IF(D8<B8,"↓ Falling","→ Stable")) -> ↑ Rising | H8: Rising % — cost inflation; watch LOE trend
A9: DD&A (Depreciation, Depletion & Amortization) | B9: =IS!B28/IS!B11 -> 0 | C9: =IS!C28/IS!C11 -> 0 | D9: =IS!D28/IS!D11 -> 0 | E9: =C9-B9 -> 0 | F9: =D9-C9 -> 0 | G9: =IF(D9>B9,"↑ Rising",IF(D9<B9,"↓ Falling","→ Stable")) -> → Stable | H9: Rising — Grayson Mill acquired assets adding to depletable base
A10: G&A Expenses | B10: =IS!B31/IS!B11 -> 0 | C10: =IS!C31/IS!C11 -> 0 | D10: =IS!D31/IS!D11 -> 0 | E10: =C10-B10 -> 0 | F10: =D10-C10 -> 0 | G10: =IF(D10>B10,"↑ Rising",IF(D10<B10,"↓ Falling","→ Stable")) -> → Stable | H10: Stable overhead leverage; slight reduction as revenue scales
A11: Financing Costs, Net | B11: =IS!B32/IS!B11 -> 0 | C11: =IS!C32/IS!C11 -> 0 | D11: =IS!D32/IS!D11 -> 0 | E11: =C11-B11 -> 0 | F11: =D11-C11 -> 0 | G11: =IF(D11>B11,"↑ Rising",IF(D11<B11,"↓ Falling","→ Stable")) -> → Stable | H11: Rising — higher debt post-Grayson acquisition (FY2024)
A12: EARNINGS BEFORE TAX MARGIN | B12: =IS!B33/IS!B11 -> 0.3029886 | C12: =IS!C33/IS!C11 -> 0.23287327 | D12: =IS!D33/IS!D11 -> 0.20165232 | E12: =C12-B12 -> -0.070115321 | F12: =D12-C12 -> -0.031220959 | G12: =IF(D12>B12,"↑ Rising",IF(D12<B12,"↓ Falling","→ Stable")) -> ↓ Falling | H12: Declining — rising costs; watch recovery with commodity prices
A13: NET PROFIT MARGIN | B13: =IS!B35/IS!B11 -> 0.24786997 | C13: =IS!C35/IS!C11 -> 0.18456713 | D13: =IS!D35/IS!D11 -> 0.15598092 | E13: =C13-B13 -> -0.063302843 | F13: =D13-C13 -> -0.02858621 | G13: =IF(D13>B13,"↑ Rising",IF(D13<B13,"↓ Falling","→ Stable")) -> ↓ Falling | H13: Declining but still strong; commodity price driven not operational
A14: EBITDAX MARGIN | B14: =IS!B51/IS!B11 -> 0.49377376 | C14: =IS!C51/IS!C11 -> 0.48550816 | D14: =IS!D51/IS!D11 -> 0.43128927 | E14: =C14-B14 -> -0.0082656024 | F14: =D14-C14 -> -0.054218884 | G14: =IF(D14>B14,"↑ Rising",IF(D14<B14,"↓ Falling","→ Stable")) -> ↓ Falling | H14: Stable high: ~43%–49% — core cash earnings quality maintained
A16: BALANCE SHEET AS % OF TOTAL ASSETS
A17: Cash & Equivalents | B17: =BS!B7/BS!B22 -> 0.035728869 | C17: =BS!C7/BS!C22 -> 0.027747712 | D17: =BS!D7/BS!D22 -> 0.045381183 | E17: =C17-B17 -> -0.0079811566 | F17: =D17-C17 -> 0.017633471 | G17: =IF(D17>B17,"↑ Rising",IF(D17<B17,"↓ Falling","→ Stable")) -> ↑ Rising | H17: Rising — liquidity buffer strengthening post-FCF accumulation
A18: Oil & Gas PP&E (net) | B18: =BS!B14/BS!B22 -> 0.73907717 | C18: =BS!C14/BS!C22 -> 0.76086457 | D18: =BS!D14/BS!D22 -> 0.75100478 | E18: =C18-B18 -> 0.0217874 | F18: =D18-C18 -> -0.0098597955 | G18: =IF(D18>B18,"↑ Rising",IF(D18<B18,"↓ Falling","→ Stable")) -> ↑ Rising | H18: Dominant asset (73.8% FY25) — capital-intensive E&P business
A19: TOTAL ASSETS (base) | B19: 1 | C19: 1 | D19: 1 | E19: =C19-B19 -> 0 | F19: =D19-C19 -> 0 | G19: =IF(D19>B19,"↑ Rising",IF(D19<B19,"↓ Falling","→ Stable")) -> → Stable | H19: Base — all BS items divided by this
A20: Long-Term Debt | B20: =BS!B35/BS!B22 -> 0.25055125 | C20: =BS!C35/BS!C22 -> 0.2754436 | D20: =BS!D35/BS!D22 -> 0.23389981 | E20: =C20-B20 -> 0.024892357 | F20: =D20-C20 -> -0.041543796 | G20: =IF(D20>B20,"↑ Rising",IF(D20<B20,"↓ Falling","→ Stable")) -> ↓ Falling | H20: Peaked FY2024 (Grayson financing); declining in FY2025 — deleveraging
A21: Total Stockholders' Equity | B21: =BS!B50/BS!B22 -> 0.49248673 | C21: =BS!C50/BS!C22 -> 0.47545016 | D21: =BS!D50/BS!D22 -> 0.49140796 | E21: =C21-B21 -> -0.017036567 | F21: =D21-C21 -> 0.015957794 | G21: =IF(D21>B21,"↑ Rising",IF(D21<B21,"↓ Falling","→ Stable")) -> ↓ Falling | H21: Rising equity ratio — balance sheet becoming increasingly equity-funded
A22: Retained Earnings | B22: =BS!B47/BS!B22 -> 0.25296039 | C22: =BS!C47/BS!C22 -> 0.2678343 | D22: =BS!D47/BS!D22 -> 0.32279503 | E22: =C22-B22 -> 0.014873909 | F22: =D22-C22 -> 0.054960724 | G22: =IF(D22>B22,"↑ Rising",IF(D22<B22,"↓ Falling","→ Stable")) -> ↑ Rising | H22: Rising sharply — profitable organic earnings retention
A24: © Owosuyi, Bamidele Tosin | Quantitative Economist, Finance & Investment Analyst | +234 916 611 2619 · bamidele.owosuyi@yahoo.com · linkedin.com/in/bamidele-owosuyi · github.com/bamideleowosuyi

Sheet PEER_COMP
A1: PEER COMPARISON & SECTOR BENCHMARKING (FY2025 DATA)
A2: Devon Energy vs Pioneer Natural Resources (FY2025e) | EOG Resources | ConocoPhillips | US E&P Sector Average
A3: Note: Competitor data represents approximate FY2025 estimates from publicly available reports/consensus. Devon FY2025 data is exact from 10-K. All values in $B or % as labelled.
A4: METRIC | B4: DEVON (FY2025) | C4: PIONEER (~FY25e) | D4: EOG (~FY25e) | E4: COP (~FY25e) | F4: SECTOR AVG | G4: DEVON RANK
A5: SCALE & SIZE
A6: Total Revenues ($B) | B6: 17.2 | C6: 22.1 | D6: 23.2 | E6: 55.8 | F6: 29.6 | G6: 🥇 Smaller but focused
A7: Total Assets ($B) | B7: 31.6 | C7: 28.5 | D7: 37.2 | E7: 95 | F7: 48.1 | G7: 🥈 Mid-size
A8: Market Cap ($B) | B8: 19.7 | C8: 34.2 | D8: 29.4 | E8: 120.5 | F8: 50.9 | G8: 🥉 Smaller by market cap
A9: PROFITABILITY
A10: EBITDAX Margin | B10: 0.431 | C10: 0.38 | D10: 0.452 | E10: 0.378 | F10: 0.41 | G10: 🥈 2nd — strong
A11: Net Profit Margin | B11: 0.156 | C11: 0.133 | D11: 0.165 | E11: 0.128 | F11: 0.146 | G11: 🥈 2nd — strong
A12: Return on Equity | B12: 0.182 | C12: 0.127 | D12: 0.195 | E12: 0.157 | F12: 0.165 | G12: 🥈 2nd — very strong
A13: Return on Assets | B13: 0.085 | C13: 0.075 | D13: 0.096 | E13: 0.052 | F13: 0.077 | G13: 🥈 2nd — above avg
A14: LIQUIDITY & LEVERAGE
A15: Current Ratio | B15: 0.98 | C15: 1.85 | D15: 2.1 | E15: 1.3 | F15: 1.56 | G15: 🥉 Below peers — watch
A16: Net Debt/EBITDAX | B16: 0.94 | C16: 0.25 | D16: 0.12 | E16: 0.48 | F16: 0.45 | G16: ❌ Most leveraged — key risk
A17: Interest Coverage (x) | B17: 7.61 | C17: 28 | D17: 45.2 | E17: 14.8 | F17: 23.9 | G17: 🥉 Lower — Grayson debt impact
A18: Equity Ratio | B18: 0.491 | C18: 0.681 | D18: 0.748 | E18: 0.502 | F18: 0.606 | G18: 🥉 Below peers
A19: CASH FLOW
A20: FCF Margin | B20: 0.182 | C20: 0.195 | D20: 0.248 | E20: 0.143 | F20: 0.192 | G20: 🥈 2nd — strong
A21: Cash Conversion | B21: 2.5 | C21: 1.95 | D21: 2.2 | E21: 2.1 | F21: 2.19 | G21: 🥇 Best — excellent OCF quality
A22: CapEx/Revenue | B22: 0.209 | C22: 0.167 | D22: 0.182 | E22: 0.172 | F22: 0.183 | G22: 🥉 Higher CapEx intensity
A23: VALUATION
A24: EV/EBITDAX (approx.) | B24: 3.7 | C24: 7.2 | D24: 6.8 | E24: 6.1 | F24: 5.95 | G24: 🥇 Cheapest — significant discount
A25: P/E (trailing, approx.) | B25: 7.5 | C25: 18.2 | D25: 15.4 | E25: 21.3 | F25: 15.6 | G25: 🥇 Cheapest — deep value signal
A26: Dividend Yield (approx.) | B26: 0.031 | C26: 0.042 | D26: 0.034 | E26: 0.032 | F26: 0.035 | G26: 🥉 Below peers — variable structure
A28: PEER SUMMARY: Devon ranks 🥇 on valuation (cheapest EV/EBITDAX 3.7x), cash conversion, and shareholder return potential. Devon lags on leverage (Net Debt/EBITDAX 0.94x vs 0.12x–0.48x for peers) and current ratio (<1.0x). The valuation discount compensates for near-term leverage headwinds, and thus suggesting attractive risk/reward for long-term investors.
A30: © Owosuyi, Bamidele Tosin | Quantitative Economist, Finance & Investment Analyst | +234 916 611 2619 · bamidele.owosuyi@yahoo.com · linkedin.com/in/bamidele-owosuyi · github.com/bamideleowosuyi

Sheet ASSUMPTIONS
A1: MODEL ASSUMPTIONS & KEY DRIVERS — UPDATE BLUE CELLS TO CHANGE THE ENTIRE MODEL
A2: COMPANY IDENTITY
A3: Company Name | B3: Devon Energy Corporation | C3: Ticker: DVN | NYSE
A4: Fiscal Year End | B4: December 31 | C4: Calendar year-end
A5: Currency | B5: USD — US Dollars | C5: $M unless stated in header
A6: Accounting Standard | B6: US GAAP | C6: ASC / FASB standards
A7: Reporting Segments | B7: Single segment | C7: All US E&P operations aggregated
A9: REVENUE ASSUMPTIONS
A10: Oil Price Realized ($/bbl) FY2025 | B10: ~$68 | C10: Embedded in $8,906M oil sales / est. volumes
A11: Gas Price Realized ($/Mcf) FY2025 | B11: ~$2.10 | C11: Embedded in $842M gas sales
A12: NGL Price Realized ($/Boe) FY2025 | B12: ~$20 | C12: Embedded in $1,475M NGL sales
A13: Revenue Growth FY2023→FY2025 | B13: 6.1% (2-yr CAGR) | C13: OGN revenue broadly flat; marketing growing
A14: Marketing Revenue as % of Total | B14: 32.4% FY2025 | C14: Growing share, but neutral to profitability
A16: COST STRUCTURE
A17: LOE per Boe (approx.) | B17: ~$7.20 | C17: FY2025: $1,922M / est. ~267 MBoe/d
A18: DD&A Rate (per Boe approx.) | B18: ~$13.50 | C18: $3,595M / est. ~266 MBoe/d
A19: G&A Rate | B19: $492M FY2025 | C19: Includes ~$99M non-cash share comp
A20: Effective Tax Rate | B20: 22.6% FY2025 | C20: ~21% federal + blended state rate
A21: Exploration Expense | B21: $43M FY2025 | C21: Dry holes and seismic costs
A23: CAPITAL STRUCTURE
A24: Total Debt FY2025 | B24: $8,389M | C24: $7,391M LT + $998M ST; avg rate ~5.5%
A25: Cash FY2025 | B25: $1,434M | C25: Including $50M restricted cash
A26: Net Debt FY2025 | B26: $6,955M | C26: Total Debt − Cash
A27: Shares Outstanding | B27: ~620M | C27: As of Feb 4, 2026 (10-K filing)
A28: Annual Buyback Budget | B28: ~$1B | C28: Consistent FY2023–FY2025 pace
A29: Fixed Dividend | B29: $0.20/share/quarter | C29: $0.80 fixed annual base
A30: Variable Dividend | B30: Commodity-linked | C30: Additional variable declared quarterly
A32: CAPITAL EXPENDITURES
A33: FY2025 Total CapEx | B33: $3,592M | C33: Organic; Delaware Basin heaviest at $1,834M
A34: FY2025 Acquisitions | B34: $322M | C34: Bolt-on acquisitions
A35: FY2026 CapEx Budget (guidance) | B35: $3,500–$3,700M | C35: ~4% below FY2025 guidance midpoint
A36: CapEx-to-Revenue | B36: 20.9% FY2025 | C36: Within OCF; self-funding capex
A37: Maintenance CapEx (est.) | B37: ~$1,500M | C37: Estimated to sustain current production
A39: BENCHMARK REFERENCES (E&P SECTOR)
A40: Current Ratio Benchmark | B40: >1.25x | C40: E&P acceptable given OCF scale
A41: Net Debt/EBITDAX Benchmark | B41: <2.0x | C41: Investment grade E&P target
A42: FCF Margin Benchmark | B42: >15% | C42: Top-quartile E&P performance
A43: ROE Benchmark | B43: >15% | C43: Large-cap US E&P
A44: EBITDAX Margin Benchmark | B44: >40% | C44: Premium E&P operators
A45: DSO Benchmark | B45: <30 days | C45: E&P typically very short payment cycles
...

Sheet FORMULA_REF
A1: MATHEMATICAL FORMULA REFERENCE (FULL DERIVATION WITH DEVON ENERGY FY2025 WORKED EXAMPLES)
A2: METRIC | B2: FORMULA (Mathematical Notation) | C2: INTERPRETATION & BENCHMARK | D2: DEVON FY2025 WORKED EXAMPLE
A3: INCOME STATEMENT
A4: Total Revenue | B4: Rev = Σ(Oil + Gas + NGL + Derivatives + Marketing) | C4: Sum of all revenue streams per ASC 606/606-10. E&P companies present gross marketing revenues. | D4: $8,906M + $842M + $1,475M + $402M + $5,563M = $17,188M
A5: Gross Profit (E&P proxy) | B5: GP = OGN Revenue − Production Expenses | C5: Upstream margin after direct production costs (LOE, GP&T, production taxes). Core operational efficiency. | D5: $11,223M − $3,567M = $7,656M (Field-Level Cash Margin per Devon disclosure)
A6: EBITDA | B6: EBITDA = Net Earnings + Tax + Net Interest + DD&A + Impairments | C6: Cash earnings proxy. Adds back non-cash and financing items. Standard comparability metric. | D6: $2,681M + $785M + $455M + $3,595M + $254M = $7,770M (approx.)
A7: EBITDAX | B7: EBITDAX = EBITDA + Exploration + Non-cash Derivatives + Other adj. | C7: Devon's preferred metric. Removes exploration volatility and derivative mark-to-market swings. | D7: $7,413M (per 10-K p.90 reconciliation — verified)
A8: Operating Margin | B8: OM% = EBT ÷ Total Revenue × 100 | C8: Pre-tax profitability of all operations including marketing. Higher = better capital discipline. | D8: $3,466M ÷ $17,188M = 20.2%
A9: Net Profit Margin | B9: NPM% = Net Earnings ÷ Total Revenue × 100 | C9: Bottom-line profitability. Benchmark: >12% for premium E&P operators. | D9: $2,681M ÷ $17,188M = 15.6%
A10: EPS (Basic) | B10: EPS_basic = Net Earnings attr. Devon ÷ Weighted Avg Basic Shares | C10: Profit per common share. Devon uses treasury stock method. Declining share count boosts EPS. | D10: $2,642M ÷ 632M shares = $4.18 per share
A11: EPS (Diluted) | B11: EPS_diluted = Net Earnings attr. Devon ÷ (Basic + Dilutive instruments) | C11: Accounts for dilutive RSUs, PSUs, stock options outstanding. | D11: $2,642M ÷ 633M shares = $4.17 per share
A12: YoY Growth % | B12: g = (Current Period − Prior Period) ÷ |Prior Period| × 100 | C12: Year-over-year percentage change. ABS(prior) handles negative base year correctly. | D12: Revenue: ($17,188M − $15,940M) ÷ $15,940M = +7.8% FY2025
A13: CAGR | B13: CAGR = (End Value ÷ Start Value)^(1/n) − 1 | C13: Compound Annual Growth Rate. Smooths multi-year growth; 2-year CAGR here (n=2). | D13: Revenue: ($17,188M/$15,258M)^(1/2) − 1 = +6.1% (FY2023→FY2025)
A14: BALANCE SHEET
A15: Accounting Equation | B15: Assets = Liabilities + Stockholders' Equity | C15: Fundamental identity. MUST always hold within ±$1M rounding. Checked by model balance check formula. | D15: $31,599M = $16,071M + $15,528M ✅ BALANCED
A16: Net Working Capital | B16: NWC = Current Assets − Current Liabilities | C16: Short-term liquidity buffer. Negative NWC common for cash-generative E&Ps funded by OCF not WC. | D16: $4,006M − $4,086M = −$80M (negative; offset by $6.7B annual OCF)
A17: Net Debt | B17: Net Debt = Total Debt − Cash & Equivalents | C17: True financial indebtedness. Companies with large cash can have low net debt vs. gross debt. | D17: ($7,391M + $998M) − $1,434M = $6,955M
A18: Book Value Per Share | B18: BVPS = Total Equity attr. Devon ÷ Shares Outstanding | C18: Net asset value per share. Declining if buybacks exceed retained earnings growth. | D18: $15,528M ÷ 620M shares = $25.04 per share
A19: LIQUIDITY RATIOS
A20: Current Ratio | B20: CR = Current Assets ÷ Current Liabilities | C20: Benchmark: >1.25x for E&P. Devon at 0.98x — technically below 1.0x but offset by $6.7B annual OCF. | D20: $4,006M ÷ $4,086M = 0.98x ⚠
A21: Quick Ratio | B21: QR = (Cash + Accounts Receivable) ÷ Current Liabilities | C21: Excludes inventory; more conservative. >1.0x = strong for immediate obligations coverage. | D21: ($1,434M + $1,792M) ÷ $4,086M = 0.79x — low but manageable
A22: Cash Ratio | B22: Cash Ratio = Cash ÷ Current Liabilities | C22: Most conservative. Even at 0.35x, Devon's daily OCF of ~$18M covers any current obligation quickly. | D22: $1,434M ÷ $4,086M = 0.35x
A23: OCF Ratio | B23: OCF Ratio = Operating CF ÷ Current Liabilities | C23: Best cash-based liquidity test for capital-intensive businesses. Devon: very strong. | D23: $6,711M ÷ $4,086M = 1.64x ✅
A24: PROFITABILITY RATIOS
A25: Return on Assets | B25: ROA = Net Earnings ÷ Average Total Assets | C25: Efficiency of total asset base. Avg assets = (Opening + Closing) ÷ 2. | D25: $2,681M ÷ (($30,489M+$31,599M)/2) = 8.6% ✅
A26: Return on Equity | B26: ROE = Net Earnings attr. Devon ÷ Avg Devon Equity | C26: Returns to common shareholders. DuPont: Margin × Turnover × Leverage. | D26: $2,642M ÷ (($14,496M+$15,528M)/2) = 17.6% ✅
A27: ROCE | B27: ROCE = EBT ÷ (Total Assets − Current Liabilities) | C27: Return on all long-term capital. Benchmark: >12% for large E&P. | D27: $3,466M ÷ ($31,599M−$4,086M) = 12.6% ✅
A28: DuPont ROE Decomposition | B28: ROE = Net Margin × Asset Turnover × Equity Multiplier | C28: Three-way decomposition: (1) profitability, (2) efficiency, (3) leverage. Identifies source of ROE. | D28: 15.6% × 0.56x × 2.03x = 17.6% (margin-driven, not leverage)
A29: LEVERAGE RATIOS
A30: Debt-to-Equity | B30: D/E = Total Debt ÷ Total Equity | C30: Higher = more financial risk. Large E&Ps typically <1.0x. Devon: comfortable. | D30: $8,389M ÷ $15,528M = 0.54x ✅
A31: Net Debt / EBITDAX | B31: ND/EBITDAX = (Total Debt − Cash) ÷ EBITDAX | C31: Primary E&P credit metric. Investment grade target: <1.5x. Devon approaching BBB+ territory. | D31: $6,955M ÷ $7,413M = 0.94x ✅ (below 1.0x)
A32: Interest Coverage Ratio | B32: ICR = (EBT + Financing Costs) ÷ Financing Costs | C32: Earnings available to service interest. >5x = safe; Devon comfortably above. | D32: ($3,466M + $455M) ÷ $455M = 8.6x ✅
A33: Solvency Ratio | B33: Solvency = Total Equity ÷ Total Assets | C33: Proportion of total assets funded by equity. Rising = financially de-risking. | D33: $15,528M ÷ $31,599M = 49.1% ✅
A34: EFFICIENCY RATIOS
A35: Days Sales Outstanding | B35: DSO = Accounts Receivable ÷ (OGN Revenue ÷ 365) | C35: Collection period. E&P norm: <30 days (monthly billing). Devon above average but improving. | D35: $1,792M ÷ ($11,223M ÷ 365) = 58.3 days ⚠
A36: Days Payable Outstanding | B36: DPO = Accounts Payable ÷ (Production Expenses ÷ 365) | C36: Payment period to suppliers. Higher = better cash flow management; watch supplier relationships. | D36: $790M ÷ ($3,567M ÷ 365) = 80.8 days ✅
A37: Asset Turnover | B37: AT = Total Revenue ÷ Average Total Assets | C37: Revenue generated per $1 of assets. E&P capital-intensive norm: 0.4–0.7x. | D37: $17,188M ÷ $31,044M avg = 0.55x ✅
A38: DD&A Per BOE (approx.) | B38: DD&A/Boe = DD&A ÷ (Daily Production × 365) | C38: Unit depletion cost; key cost metric for E&P. Lower = more reserves coverage remaining. | D38: $3,595M ÷ (~266 MBoe/d × 365) = ~$37/Boe
A39: CASH FLOW RATIOS
A40: Free Cash Flow | B40: FCF = Operating Cash Flow − Capital Expenditures (organic) | C40: Primary value creation metric. Must fund dividends, buybacks, debt service without external capital. | D40: $6,711M − $3,592M = $3,119M FCF ✅
...
